<?xml version="1.0" encoding="UTF-8"?>
<robot name="DONKEYBOTI" xmlns:xacro="http://www.ros.org/wiki/xacro">

    <material name="black">
        <color rgba="0.0 0.0 0.0 1.0"/>
    </material>

    <material name="dark">
        <color rgba="0.3 0.3 0.3 1.0"/>
    </material>

    <material name="light_black">
        <color rgba="0.4 0.4 0.4 1.0"/>
    </material>

    <material name="blue">
        <color rgba="0.0 0.0 0.8 1.0"/>
    </material>

    <material name="green">
        <color rgba="0.0 0.8 0.0 1.0"/>
    </material>

    <material name="grey">
        <color rgba="0.5 0.5 0.5 1.0"/>
    </material>

    <material name="orange">
        <color rgba="1.0 0.4235 0.0392 1.0"/>
    </material>

    <material name="brown">
        <color rgba="0.8706 0.8118 0.7647 1.0"/>
    </material>

    <material name="red">
        <color rgba="0.8 0.0 0.0 1.0"/>
    </material>

    <material name="white">
        <color rgba="1.0 1.0 1.0 1.0"/>
    </material>

    <material name="yellow">
        <color rgba="1.0 1.0 0.0 1.0"/>
    </material>

    <link name="base_footprint"/>

    <joint name="base_joint" type="fixed">
        <origin xyz="0.0 0.0 0.1005" rpy="0.0 0.0 0.0"/>
        <parent link="base_footprint"/>
        <child link="base_link"/>
    </joint>

    <link name="base_link">
        <visual>
            <origin xyz="0.942 0.326 -0.1005" rpy="1.57 0.0 -1.57"/>
            <geometry>
                <mesh filename="package://omorobot_description/meshes/bases/DONKEYBOTI_BODY.stl" scale="0.001 0.001 0.001"/>
            </geometry>
            <material name="yellow"/>
        </visual>
    </link>

    <joint name="wheel_left_joint" type="continuous">
        <origin xyz="0.0 0.283 0.0" rpy="-1.57 0.0 0.0"/>
        <parent link="base_link"/>
        <child link="wheel_left_link"/>
        <axis xyz="0.0 0.0 1.0"/>
    </joint>

    <link name="wheel_left_link">
        <visual>
            <origin xyz="-0.1005 -0.1005 0.0275" rpy="0.0 1.57 0.0"/>
            <geometry>
                <mesh filename="package://omorobot_description/meshes/wheels/DONKEYBOTI_WHEEL.stl" scale="0.001 0.001 0.001"/>
            </geometry>
            <material name="blue"/>
        </visual>
    </link>

    <joint name="wheel_right_joint" type="continuous">
        <origin xyz="0.0 -0.283 0.0" rpy="-1.57 0.0 0.0"/>
        <parent link="base_link"/>
        <child link="wheel_right_link"/>
        <axis xyz="0.0 0.0 1.0"/>
    </joint>

    <link name="wheel_right_link">
        <visual>
            <origin xyz="-0.1005 -0.1005 0.0275" rpy="0.0 1.57 0.0"/>
            <geometry>
                <mesh filename="package://omorobot_description/meshes/wheels/DONKEYBOTI_WHEEL.stl" scale="0.001 0.001 0.001"/>
            </geometry>
            <material name="blue"/>
        </visual>
    </link>

    <joint name="imu_joint" type="fixed">
        <origin xyz="0.0 0.0 0.0" rpy="0.0 0.0 1.57"/>
        <parent link="base_link"/>
        <child link="imu_link"/>
    </joint>

    <link name="imu_link">
    </link>

    <joint name="scan_joint" type="fixed">
        <origin xyz="-0.335 0.0 0.432" rpy="0.0 0.0 0.0"/>
        <parent link="base_link"/>
        <child link="base_scan"/>
        <axis xyz="0.0 0.0 0.0"/>
    </joint>

    <link name="base_scan">
        <visual>
            <origin xyz="0.02 -0.02 0.0" rpy="0.0 0.0 1.57"/>
            <geometry>
                <mesh filename="package://omorobot_description/meshes/sensors/TMINIPRO.stl" scale="0.001 0.001 0.001"/>
            </geometry>
            <material name="green"/>
        </visual>
    </link>
</robot>
