<?xml version="1.0" encoding="UTF-8"?>
<robot name="R2" xmlns:xacro="http://www.ros.org/wiki/xacro">

    <material name="black">
        <color rgba="0.0 0.0 0.0 1.0"/>
    </material>

    <material name="dark">
        <color rgba="0.3 0.3 0.3 1.0"/>
    </material>

    <material name="light_black">
        <color rgba="0.4 0.4 0.4 1.0"/>
    </material>

    <material name="blue">
        <color rgba="0.0 0.0 0.8 1.0"/>
    </material>

    <material name="green">
        <color rgba="0.0 0.8 0.0 1.0"/>
    </material>

    <material name="grey">
        <color rgba="0.5 0.5 0.5 1.0"/>
    </material>

    <material name="orange">
        <color rgba="1.0 0.4235 0.0392 1.0"/>
    </material>

    <material name="brown">
        <color rgba="0.8706 0.8118 0.7647 1.0"/>
    </material>

    <material name="red">
        <color rgba="0.8 0.0 0.0 1.0"/>
    </material>

    <material name="white">
        <color rgba="1.0 1.0 1.0 1.0"/>
    </material>

    <material name="yellow">
        <color rgba="1.0 1.0 0.0 1.0"/>
    </material>

    <link name="base_footprint"/>

    <joint name="base_joint" type="fixed">
        <origin xyz="0.0 0.0 0.065" rpy="0.0 0.0 0.0"/>
        <parent link="base_footprint"/>
        <child link="base_link"/>
    </joint>

    <link name="base_link">
        <visual>
            <origin xyz="0.097 0.276 0.19" rpy="3.14 0.0 -1.57"/>
            <geometry>
              <mesh filename="package://omorobot_description/meshes/bases/R2_BODY.stl" scale="0.001 0.001 0.001"/>
            </geometry>
            <material name="red"/>
        </visual>
        <collision>
            <origin xyz="0.097 0.276 0.19" rpy="3.14 0.0 -1.57"/>
            <geometry>
                <mesh filename="package://omorobot_description/meshes/bases/R2_BODY.stl" scale="0.001 0.001 0.001"/>
            </geometry>
        </collision>
    </link>

    <joint name="wheel_left_joint" type="continuous">
        <origin xyz="0.0 0.285 0.035" rpy="0.0 0.0 0.0"/>
        <parent link="base_link"/>
        <child link="wheel_left_link"/>
        <axis xyz="0.0 1.0 0.0"/>
    </joint>

    <link name="wheel_left_link">
      <visual>
          <origin xyz="-0.1105 -0.07 0.1104" rpy="-1.57 0.0 0.0"/>
          <geometry>
            <mesh filename="package://omorobot_description/meshes/wheels/R2_WHEEL.stl" scale="0.001 0.001 0.001"/>
          </geometry>
          <material name="blue"/>
      </visual>
      <collision>
          <origin xyz="-0.1105 -0.06 0.1104" rpy="-1.57 0.0 0.0"/>
          <geometry>
              <mesh filename="package://omorobot_description/meshes/wheels/R2_WHEEL.stl" scale="0.001 0.001 0.001"/>
          </geometry>
      </collision>
    </link>

    <joint name="wheel_right_joint" type="continuous">
        <origin xyz="0.0 -0.285 0.035" rpy="0.0 0.0 0.0"/>
        <parent link="base_link"/>
        <child link="wheel_right_link"/>
        <axis xyz="0.0 1.0 0.0"/>
    </joint>

    <link name="wheel_right_link">
      <visual>
          <origin xyz="-0.110 0.07 -0.1103" rpy="1.57 0.0 0.0"/>
          <geometry>
              <mesh filename="package://omorobot_description/meshes/wheels/R2_WHEEL.stl" scale="0.001 0.001 0.001"/>
          </geometry>
          <material name="blue"/>
      </visual>
      <collision>
          <origin xyz="-0.110 0.06 -0.1103" rpy="1.57 0.0 0.0"/>
          <geometry>
              <mesh filename="package://omorobot_description/meshes/wheels/R2_WHEEL.stl" scale="0.001 0.001 0.001"/>
          </geometry>
      </collision>
    </link>

    <joint name="caster_back_right_joint" type="fixed">
        <origin xyz="-0.33 -0.148 0.06" rpy="0.0 0.0 0.0"/>
        <parent link="base_link"/>
        <child link="caster_back_right_link"/>
    </joint>

    <link name="caster_back_right_link">
        <collision>
            <origin xyz="0.0 0.0 -0.133" rpy="0.0 0.0 0.0"/>
            <geometry>
                <box size="0.01 0.01 0.01"/>
            </geometry>
        </collision>
    </link>

    <joint name="caster_back_left_joint" type="fixed">
        <origin xyz="-0.33 0.148 0.06" rpy="0.0 0.0 0.0"/>
        <parent link="base_link"/>
        <child link="caster_back_left_link"/>
    </joint>

    <link name="caster_back_left_link">
        <collision>
            <origin xyz="0.0 0.0 -0.133" rpy="0.0 0.0 0.0"/>
            <geometry>
                <box size="0.01 0.01 0.01"/>
            </geometry>
        </collision>
    </link>

    <joint name="imu_joint" type="fixed">
        <origin xyz="0.0 0.0 0.19" rpy="0.0 0.0 1.57"/>
        <parent link="base_link"/>
        <child link="imu_link"/>
    </joint>

    <link name="imu_link"/>

    <joint name="scan_joint" type="fixed">
        <origin xyz="0.06 0.0 0.23" rpy="0.0 0.0 0.0"/>
        <parent link="base_link"/>
        <child link="base_scan"/>
        <axis xyz="0.0 0.0 0.0"/>
    </joint>

    <link name="base_scan">
        <visual>
            <origin xyz="0.0 0.0 0.0" rpy="0.0 0.0 0.0"/>
            <geometry>
                <mesh filename="package://omorobot_description/meshes/sensors/R2_LIDAR.stl" scale="0.001 0.001 0.001"/>
            </geometry>
            <material name="green"/>
        </visual>
        <collision>
            <origin xyz="0.0 0.0 0.0" rpy="0.0 0.0 0.0"/>
            <geometry>
                <mesh filename="package://omorobot_description/meshes/sensors/R2_LIDAR.stl" scale="0.001 0.001 0.001"/>
            </geometry>
        </collision>
    </link>

</robot>
